(dp1
S'output'
p2
S'<type \'exceptions.RuntimeError\'> Failure to connect, tried 5 times:\nTraceback (most recent call last):\n  File "/home/alvaro/Descargas/web2py/gluon/packages/dal/pydal/base.py", line 446, in __init__\n    self._adapter = ADAPTERS[self._dbname](**kwargs)\n  File "/home/alvaro/Descargas/web2py/gluon/packages/dal/pydal/adapters/base.py", line 60, in __call__\n    obj = super(AdapterMeta, cls).__call__(*args, **kwargs)\n  File "/home/alvaro/Descargas/web2py/gluon/packages/dal/pydal/adapters/mysql.py", line 132, in __init__\n    if do_connect: self.reconnect()\n  File "/home/alvaro/Descargas/web2py/gluon/packages/dal/pydal/connection.py", line 125, in reconnect\n    self.connection = f()\n  File "/home/alvaro/Descargas/web2py/gluon/packages/dal/pydal/adapters/mysql.py", line 130, in connector\n    return self.driver.connect(**driver_args)\n  File "/usr/lib/python2.7/dist-packages/MySQLdb/__init__.py", line 81, in Connect\n    return Connection(*args, **kwargs)\n  File "/usr/lib/python2.7/dist-packages/MySQLdb/connections.py", line 187, in __init__\n    super(Connection, self).__init__(*args, **kwargs2)\nOperationalError: (1049, "Unknown database \'pi\'")\n'
p3
sS'layer'
p4
S'/home/alvaro/Descargas/web2py/applications/pi/models/db.py'
p5
sS'code'
p6
S"# -*- coding: utf-8 -*-\ndb = DAL('mysql://root:asdf1234@localhost/pi', pool_size=1)\ninstall = True\n"
p7
sS'snapshot'
p8
(dp9
sS'traceback'
p10
S'Traceback (most recent call last):\n  File "/home/alvaro/Descargas/web2py/gluon/restricted.py", line 227, in restricted\n    exec ccode in environment\n  File "/home/alvaro/Descargas/web2py/applications/pi/models/db.py", line 2, in <module>\n    db = DAL(\'mysql://root:asdf1234@localhost/pi\', pool_size=1)\n  File "/home/alvaro/Descargas/web2py/gluon/packages/dal/pydal/base.py", line 174, in __call__\n    obj = super(MetaDAL, cls).__call__(*args, **kwargs)\n  File "/home/alvaro/Descargas/web2py/gluon/packages/dal/pydal/base.py", line 473, in __init__\n    "Failure to connect, tried %d times:\\n%s" % (attempts, tb)\nRuntimeError: Failure to connect, tried 5 times:\nTraceback (most recent call last):\n  File "/home/alvaro/Descargas/web2py/gluon/packages/dal/pydal/base.py", line 446, in __init__\n    self._adapter = ADAPTERS[self._dbname](**kwargs)\n  File "/home/alvaro/Descargas/web2py/gluon/packages/dal/pydal/adapters/base.py", line 60, in __call__\n    obj = super(AdapterMeta, cls).__call__(*args, **kwargs)\n  File "/home/alvaro/Descargas/web2py/gluon/packages/dal/pydal/adapters/mysql.py", line 132, in __init__\n    if do_connect: self.reconnect()\n  File "/home/alvaro/Descargas/web2py/gluon/packages/dal/pydal/connection.py", line 125, in reconnect\n    self.connection = f()\n  File "/home/alvaro/Descargas/web2py/gluon/packages/dal/pydal/adapters/mysql.py", line 130, in connector\n    return self.driver.connect(**driver_args)\n  File "/usr/lib/python2.7/dist-packages/MySQLdb/__init__.py", line 81, in Connect\n    return Connection(*args, **kwargs)\n  File "/usr/lib/python2.7/dist-packages/MySQLdb/connections.py", line 187, in __init__\n    super(Connection, self).__init__(*args, **kwargs2)\nOperationalError: (1049, "Unknown database \'pi\'")\n\n'
p11
s.